Workbook
Name AfterTaxA: Input!$C$5
Name AfterTaxB: Input!$C$8
Name BaseRepayment: Input!$C$41
Name CapIncrement: Input!$C$32
Name CapIndexYears: Input!$C$33
Name CarryFwdStartA: Input!$C$25
Name CarryFwdStartB: Input!$C$26
Name ConcessCap: Input!$C$23
Name CurrentAgeA: Input!$C$11
Name CurrentAgeB: Input!$C$12
Name Div293Thresh: Input!$C$29
Name ExtraRepay: Input!$C$44
Name FreqA: Input!$C$4
Name FreqB: Input!$C$7
Name IncA: Input!$C$3
Name IncB: Input!$C$6
Name Inflation: Input!$C$13
Name LoanAmount: Input!$C$37
Name LoanRate: Input!$C$38
Name LoanStart: Input!$C$40
Name LoanTerm: Input!$C$39
Name MedicareRate: Input!$C$20
Name MRate: _xlfn.LAMBDA(_xlpm.inc, _xlfn.LET( _xlpm.brackets, PersonaB!TaxBracket, _xlpm.rate, _xlfn.XLOOKUP(_xlpm.inc, INDEX(_xlpm.brackets,0,1), INDEX(_xlpm.brackets,0,3),,-1), _xlpm.rate+0.02))
Name NetInvLoss: Input!$C$30
Name OffsetStart: Input!$C$43
Name PersonATaxPayable: Input!$C$9
Name PersonBTaxPayable: Input!$C$10
Name PPY: Offset!$V$3
Name PPY_Loan: Loan!$AY$2
Name PPYA: PersonaA!$W$3
Name PPYB: PersonaB!$W$3
Name ProjYears: Input!$C$15
Name ProjYearsA: Input!$C$14
Name ProjYearsB: Input!$C$15
Name RetirementAgeA: Input!$C$17
Name RetirementAgeB: Input!$C$17
Name SGRate: Input!$C$24
Name SpousalTransfer: Input!$C$50
Name StartYear: Input!$C$16
Name StdPayment: Loan!$AY$4
Name SuperBalStartA: Input!$C$27
Name SuperBalStartB: Input!$C$28
Name SuperReturn: Input!$C$31
Name SuperTaxRate: Input!$C$34
Name TaxBracket: TaxBracketsOrig[]
Name TaxBracket: TaxBracketsOrig[]
Name TaxBracket: TaxBracketsOrig[]
Name TotalPeriods_Loan: Loan!$AY$3
Name TotalPeriodsA: PersonaA!$W$4
Name TotalPeriodsB: PersonaB!$W$4
Name TotalPeriodsB: PersonaB!$W$4
Name TotalPeriodsOffset: Offset!$V$4
Name TransferDir: Input!$C$51

Sheet README
A1: SUPERSMART MORTGAGE STRATEGY MODEL 2.0
A2: README — Model Guide & Methodology
B4: ① PROJECT OVERVIEW | D4: ② HOW THE STRATEGY WORKS
B5: This model implements an Australian tax-optimised mortgage repayment strategy ("SuperSmart") that coordinates salary sacrifice to superannuation, offset account accumulation, and annual sweeps to accelerate mortgage payoff while maximising lifetime tax savings. | D5: The SuperSmart strategy works in three coordinated stages each financial year:
B6: Client Requirements Met: | D6: Step 1 — Salary Sacrifice to Super (Tax Reduction)
B7: ✅ Dual-persona tax modelling (Person A & B with different incomes, ages, retirement horizons) | D7: Each persona redirects pre-tax income into superannuation up to their allowable concessional cap (including carry-forward from unused prior years). This reduces taxable income from the marginal rate (up to 47% incl. Medicare) to the 15% super contributions tax — saving up to 32 cents per dollar contributed.
B8: ✅ Three-scenario mortgage comparison (No Strategy / Extra Repayments / SuperSmart with Offset)
B9: ✅ Carry-forward concessional cap utilisation with 5-year rolling tracker and spousal transfers | D9: Step 2 — Offset Account Accumulation (Interest Reduction)
B10: ✅ Division 293 high-earner surcharge modelling and Medicare levy integration | D10: The tax-saved funds are deposited into a mortgage offset account each pay period. While sitting in offset, the balance directly reduces the effective mortgage principal that accrues interest. For example, a $400K offset against a $1.8M loan means interest accrues on $1.4M only.
B11: ✅ Monthly-granularity offset account with annual sweep-to-mortgage mechanism
B12: ✅ Inflation-adjusted projections with dynamic SG rate and concessional cap indexation | D12: Step 3 — Annual Sweep to Mortgage (Principal Acceleration)
B13: ✅ 28 advanced DAX measures with Power BI-ready formulas for portfolio dashboarding | D13: At the end of each financial year, the accumulated offset balance is swept as a lump-sum extra repayment against the loan principal. This permanently reduces the outstanding balance, creating a compounding effect: each year's sweep means the following year's interest is lower, accelerating payoff.
B14: ✅ Executive dashboard with KPI scorecards, 6 charts, and conditional-formatted summary
B15: ③ SHEET-BY-SHEET GUIDE | D15: ④ DATA FLOW & FORMULA CHAIN
B16: Navigate the model using this flow: Input → Engine Sheets → Summary → Dashboard | D16: Every output is formula-driven. No hardcoded results. Change any input and all 11 sheets recalculate.
B17: 📘 Dashboard (Start Here) | D17: Layer 1: Input Parameters
B18: Executive summary with 4 KPI scorecards (Tax Saved, Interest Saved, Super Wealth, ROI) and 6 visualisations. All values are formula-linked — changes to Input flow through automatically. | D18: Input sheet → Named ranges (IncA, IncB, LoanRate, LoanAmount, etc.) feed all downstream sheets via absolute references.
B19: 📊 Measures | D19: Layer 2: Tax Engine
B20: 28 advanced KPIs across 4 categories: Strategy Efficiency, Mortgage Acceleration, Super & Wealth, Risk & Sensitivity. Each row has the computed value, plain-English description, and a copy-pasteable Power BI DAX measure. | D20: Tax Helper calculates marginal rates and tax payable → feeds PersonaA/B with each persona's marginal rate and the base pre-tax contribution amount per period.
B21: ⚙️ Input (Client Configuration) | D21: Layer 3: Contribution Engines
B22: All client-specific parameters: incomes, ages, super balances, carry-forward, mortgage terms, SG rate, Div 293 threshold, inflation. Blue text = change per client. Yellow = system assumptions. Green = formula-derived (do not edit). The Live Model Preview panel on the right shows real-time impacts. | D22: PersonaA/B compute monthly salary sacrifice amounts → tax saved per period → deposits to Offset. YearlyParamsA/B track annual carry-forward, SG, Div 293, and cap indexation.
B23: 💰 Tax Helper | D23: Layer 4: Mortgage & Offset
B24: Australian marginal tax table with Medicare levy. Calculates tax payable with and without the strategy for both personas. Produces the 'Year 1 Tax Saved' and 'Lifetime Tax Saved' headline figures. Uses the ATO 2024–25 tax brackets. | D24: Offset accumulates monthly deposits → reduces effective balance in Loan sheet → annual sweep resets offset to zero and applies lump sum to principal. Loan runs 3 parallel amortisation schedules.
B25: 👤 PersonaA / PersonaB (Contribution Engines) | D25: Layer 5: Aggregation & Output
B26: Monthly-granularity salary sacrifice calculators for each persona. Tracks: base pre-tax contribution, carry-forward allowance, actual contribution, tax saved per period, cumulative YTD totals. Handles the carry-forward burn sequence and spousal transfer logic. | D26: YearlySummary aggregates all engines into 34-column yearly table → Measures derives 28 KPIs from YearlySummary → Dashboard visualises the headline outputs.
... B34: The model's core output table — one row per projection year with 34 columns covering: contributions, tax saved, cumulative tax saved, super balances, loan balances (all 3 scenarios), interest saved, sweep amounts, offset peak, employer SG, carry-forward remaining, Div 293 tax, and savings rates. This sheet feeds the Dashboard and Measures. | D34: • Offset sweep: Annual frequency at end of financial year (June 30).
B35: ⑥ QUICK-START: HOW TO USE
B36: Step 1 — Enter Client Details
B37: Go to the Input sheet. Update the blue-text cells in sections ①–⑤: gross incomes, ages, super balances, carry-forward balances, loan amount, interest rate, and loan term. Leave green-text (formula) cells untouched.
B39: Step 2 — Verify Tax Calculation
B40: Check the Tax Helper sheet — confirm the marginal rates and tax payable figures match the client's latest tax assessment. The 'WITH SuperSmart' section should show the reduced taxable income after salary sacrifice.
B42: Step 3 — Review the Dashboard
B43: Navigate to Dashboard for the executive summary. The 4 KPI cards show headline metrics. Scroll down for the loan trajectory chart (3 scenarios), cumulative tax saved, super growth, and contribution breakdown.
B45: Step 4 — Deep-Dive with Measures
B46: The Measures sheet provides 28 KPIs with descriptions. Use these to answer client questions: 'What's my break-even super return?' (B35), 'How much risk is front-loaded in Year 1?' (B39), 'What's the real benefit after inflation?' (B37).
B48: Step 5 — Scenario Analysis
B49: Adjust Input parameters to test scenarios: change the interest rate (C38), super return (C31), or inflation rate (C13) and watch all sheets recalculate. Compare the Dashboard before/after to quantify the impact.
B51: Step 6 — Export to Power BI (Optional)
B52: Column D of the Measures sheet contains valid Power BI DAX measures. To use: (1) Import this workbook into Power BI via Get Data > Excel, (2) Create relationships between Input, YearlySummary, and Loan tables, (3) Copy each DAX formula from column D into New Measure in Power BI Desktop.

Sheet Input
B2: ① Personal & Income | E2: 📋 INPUT GUIDE
B3: Annual Gross Income - Person A | C3: 145000 | D3: =IF(C3>=250000,"⚠ Div293","") | E3: Blue text | F3: Client-specific (change per client)
B4: Pay Frequency - Person A | C4: Monthly | E4: Yellow cells | F4: System assumptions (rarely changed)
B5: Desired After-Tax Contribution - Person A | C5: 7000 | E5: Green text | F5: Calculated (formula-derived)
B6: Annual Gross Income - Person B | C6: 230000 | D6: =IF(C6>=250000,"⚠ Div293","")
B7: Pay Frequency - Person B | C7: Monthly
B8: Desired After-Tax Contribution - Person B | C8: 5000
B9: Person A Tax Payable | C9: ='Tax Helper'!C33 -> 37620
B10: Person B Tax Payable | C10: ='Tax Helper'!D33 -> 73970
B11: Current Age - Person A | C11: 53 | E11: LIVE MODEL PREVIEW
B12: Current Age - Person B | C12: 50 | E12: Tax & Income
B13: Inflation Rate (annual) | C13: 0.025 | E13: Combined Gross Income | F13: =IncA+IncB -> 375000
B14: Projection Years (to Retirement) A | C14: =RetirementAgeA-CurrentAgeA -> 12 | E14: Effective Tax Rate (no strategy) | F14: ='Tax Helper'!E35 -> 0.29757333
B15: Projection Years (to Retirement) B | C15: =RetirementAgeB-CurrentAgeB -> 15 | E15: Lifetime Tax Payable (no strategy) | F15: ='Tax Helper'!E53 -> 1979490
B16: Start Date (enter as date e.g. 1/07/2027) | C16: 46388 | E16: Year 1 Tax Saved | F16: ='Tax Helper'!E46 -> 77750
B17: Retirement Age Person | C17: 65 | E17: Lifetime Tax Saved | F17: ='Tax Helper'!E47 -> 254263.08
B18: Total Lifetime tax payable | C18: ='Tax Helper'!E53 -> 1979490 | D18: =IF(C17>67,"⚠ Past preservation","")
B19: ② Medicare | E19: Monthly Repayment | F19: =StdPayment -> 27061.315
B20: Medicare Rate | C20: 0.02 | E20: Extra Repay (converted) | F20: =IF(C42=0,0,C42*52/PPY_Loan) -> 650
E21: Payoff (Scenario A) | F21: =IF(ISNUMBER(Loan!AR8), ROUND(Loan!AR8,1)&" yrs", ">"&ProjYears&" yrs") -> 12.1 yrs
B22: ③ Superannuation Parameters | E22: Payoff (SuperSmart) | F22: =IF(ISNUMBER(Loan!AV8), ROUND(Loan!AV8,1)&" yrs", ">"&ProjYears&" yrs") -> 11.8 yrs
B23: Concessional contribution cap (including SG) | C23: 32500 | E23: Interest Saved | F23: ='Tax Helper'!E49 -> 30271.925
B24: SG rate | C24: 0.12
B25: Carry-Forward Balance - Person A | C25: 70000 | E25: Super & Strategy
B26: Carry-Forward Balance - Person B | C26: 120000 | E26: Yr 1 Contribution (combined) | F26: =YearlySummary!E2 -> 210000
B27: Super Balance - Person A (for carry-forward eligibility) | C27: 180000 | E27: Combined Benefit (lifetime) | F27: ='Tax Helper'!E50 -> 560308.13
B28: Super Balance - Person B (for carry-forward eligibility) | C28: 200000 | D28: =IF(C27>=500000,"⚠ No carry-fwd","")
B29: Division 293 threshold | C29: 250000 | D29: =IF(C28>=500000,"⚠ No carry-fwd","")
B30: Net Investment Losses | C30: 0
B31: Assumed super investment return p.a. | C31: 0.07
B32: Indexation increment for cap ($2,500 every 2 years) | C32: 2500
B33: Years between cap indexation | C33: 2
B34: Super contributions tax rate (inside fund) | C34: 0.15
B36: ④ Mortgage Parameters
B37: Loan Amount | C37: 2500000
B38: Annual Interest Rate | C38: 0.08
B39: Loan Term(Years) | C39: 12
B40: Start Date | C40: =StartYear -> 46388
B41: Base Repayment | C41: 8000
B42: Extra Repayment (weekly equivalent, optional) | C42: 150
...

Sheet Tax Helper
G1: {=TaxPayable(F1)} -> 0
B2: Medicare | C2: =MedicareRate -> 0.02 | F2: {=TaxPayable(280000)+TaxPayable(287000)+TaxPayable(294175)+TaxPayable(301529.375)+TaxPayable(309067.609375)+TaxPayable(316794.299609375)+TaxPayable(324714.157099609)+TaxPayable(332832.0110271)+TaxPayable(341152.811302777)+TaxPayable(349681.631585346)+TaxPayable(358423.67237498)+TaxPayable(367384.264184354)+TaxPayable(376568.870788963)+TaxPayable(385983.092558687)+TaxPayable(395632.669872654)+TaxPayable(405523.486619471)+TaxPayable(415661.573784958)} -> 2165588.5 | G2: {=TaxPayable(F17)} -> 0
B3: Income | C3: =IncA -> 145000
B5: Tax Table
B6: Lower Limit | C6: Upper Limit | D6: Rate | E6: Adjusted Rate(Medicare Inc)
B7: 0 | C7: 18200 | D7: 0 | E7: =D7+0.02 -> 0.02
B8: =C7+1 -> 18201 | C8: 45000 | D8: 0.15 | E8: =D8+0.02 -> 0.17
B9: =C8+1 -> 45001 | C9: 135000 | D9: 0.3 | E9: =D9+0.02 -> 0.32
B10: =C9+1 -> 135001 | C10: 190000 | D10: 0.37 | E10: =D10+0.02 -> 0.39
B11: =C10+1 -> 190001 | C11: 99999999 | D11: 0.45 | E11: =D11+0.02 -> 0.47
B13: Adjusted Tax Table
B14: Lower Limit | C14: Upper Limit | D14: Rate
B15: 0 | C15: 18200 | D15: 0
B16: =C15 -> 18200 | C16: 45000 | D16: 0.15
B17: =C16 -> 45000 | C17: 135000 | D17: 0.3
B18: =C17 -> 135000 | C18: 190000 | D18: 0.37
B19: =C18 -> 190000 | C19: 99999999 | D19: 0.45
B22: Marginal Tax Rate | C22: {=MRate($C$3)} -> 0.39
B23: Tax payable | C23: {=TaxPayable($C$3)} -> 37620
B25: Tax Comparison: Without vs With SuperSmart
C27: Person A | D27: Person B | E27: Combined
B28: WITHOUT SuperSmart (Current Position)
B29: Annual Gross Income | C29: =IncA -> 145000 | D29: =IncB -> 230000 | E29: =C29+D29 -> 375000
B30: Marginal Tax Rate (incl. Medicare) | C30: {=MRate(IncA)} -> 0.39 | D30: {=MRate(IncB)} -> 0.47
B31: Income Tax Payable (excl. Medicare) | C31: {=TaxPayable(IncA)-IncA*MedicareRate} -> 34720 | D31: {=TaxPayable(IncB)-IncB*MedicareRate} -> 69370 | E31: =C31+D31 -> 104090
B32: Medicare Levy (2%) | C32: =IncA*MedicareRate -> 2900 | D32: =IncB*MedicareRate -> 4600 | E32: =C32+D32 -> 7500
B33: Total Tax Payable | C33: {=TaxPayable(IncA)} -> 37620 | D33: {=TaxPayable(IncB)} -> 73970 | E33: =C33+D33 -> 111590
B34: After-Tax Income | C34: =IncA-C33 -> 107380 | D34: =IncB-D33 -> 156030 | E34: =C34+D34 -> 263410
B35: Effective Tax Rate | C35: =C33/IncA -> 0.25944828 | D35: =D33/IncB -> 0.3216087 | E35: =E33/E29 -> 0.29757333
B37: WITH SuperSmart (Year 1)
B38: Annual Gross Income | C38: =IncA -> 145000 | D38: =IncB -> 230000 | E38: =C38+D38 -> 375000
B39: Year 1 Personal Super Contribution | C39: =IFERROR(_xlfn.XLOOKUP(YEAR(StartYear), YearlyParamsA!A:A, YearlyParamsA!AA:AA, 0), 0) -> 85100 | D39: =IFERROR(_xlfn.XLOOKUP(YEAR(StartYear), YearlyParamsB!A:A, YearlyParamsB!AB:AB, 0), 0) -> 124900 | E39: =C39+D39 -> 210000
B40: Reduced Taxable Income | C40: =C38-C39 -> 59900 | D40: =D38-D39 -> 105100 | E40: =C40+D40 -> 165000
B41: Total Tax Payable (on reduced income) | C41: {=TaxPayable(C40)} -> 9688 | D41: {=TaxPayable(D40)} -> 24152 | E41: =C41+D41 -> 33840
B42: After-Tax Income (before super contribution) | C42: =C40-C41 -> 50212 | D42: =D40-D41 -> 80948 | E42: =C42+D42 -> 131160
B43: Effective Tax Rate | C43: =IF(C38=0,0,C41/C38) -> 0.066813793 | D43: =IF(D38=0,0,D41/D38) -> 0.1050087 | E43: =IF(E38=0,0,E41/E38) -> 0.09024
B45: TAX SAVINGS (Year 1)
B46: Tax Savings (Year 1) | C46: =C33-C41 -> 27932 | D46: =D33-D41 -> 49818 | E46: =E33-E41 -> 77750
B47: Lifetime Super Balance | C47: =IFERROR(_xlfn.XLOOKUP(YEAR(StartYear)+ProjYearsA-1, PersonaA!B:B, PersonaA!S:S,,,-1), 0) -> 122649.62 | D47: =IFERROR(_xlfn.XLOOKUP(YEAR(StartYear)+ProjYearsB-1, PersonaB!B:B, PersonaB!S:S,,,-1), 0) -> 131613.46 | E47: =C47+D47 -> 254263.08
B48: Lifetime Tax Saved | C48: =IFERROR(SUM(_xlfn.XLOOKUP(YEAR(StartYear), YearlyParamsA!A:A, YearlyParamsA!AA:AA):_xlfn.XLOOKUP(YEAR(StartYear)+ProjYearsA-1, YearlyParamsA!A:A, YearlyParamsA!AA:AA)), 0) -> 188674.72 | D48: =IFERROR(SUM(_xlfn.XLOOKUP(YEAR(StartYear), YearlyParamsB!A:A, YearlyParamsB!AB:AB):_xlfn.XLOOKUP(YEAR(StartYear)+ProjYearsB-1, YearlyParamsB!A:A, YearlyParamsB!AB:AB)), 0) -> 341361.49 | E48: =C48+D48 -> 530036.2
...

Sheet PersonaA
A1: Period | B1: Year | C1: PeriodInYear | D1: IsSweepPeriod | E1: AnnualIncome | F1: MarginalRate | G1: BasePreTax | H1: CarryFwdThisYear | I1: EmployerSGAnnual | J1: AllowablePersonalAnnual | K1: CumulativePrev | L1: TaxSavedPrev | M1: ClientPreTaxContrib | N1: AvailableRoom | O1: ClientContribution | P1: TotalTaxBenefit | Q1: CumulativeSuperYTD | R1: CumulativeTaxSavedYTD | S1: CumulativeTaxSavedTotal
A2: =IF(ROW()-1 <= TotalPeriodsA, ROW()-1, "") -> 1 | B2: =IF(ROW()-1 <= TotalPeriodsA, YEAR(StartYear) + INT((ROW()-2)/PPYA), "") -> 2027 | C2: =IF($A2="", "", MOD($A2-1, PPYA)+1) -> 1 | D2: =IF($A2="", "", C2=PPYA) -> FALSE | E2: =IF($A2="","",IncA*(1+Inflation)^((B2 - YEAR(StartYear)))) -> 145000 | F2: {=IF($A2="", "", MRate(E2))} -> 0.39 | G2: =IF($A2="", "", AfterTaxA/(1-F2)) -> 11475.41 | H2: =IF($A2="", "", _xlfn.XLOOKUP($B2, YearlyParamsA!$A:$A, YearlyParamsA!$E:$E, 0)) -> 70000 | I2: =IF($A2="", "", E2*SGRate) -> 17400 | J2: =IFERROR(IF($A2="", "", _xlfn.XLOOKUP($B2, YearlyParamsA!$A:$A, YearlyParamsA!$I:$I, 0)), 0) -> 85100 | K2: =IF($A2="", "", 0) -> 0 | L2: =IF($A2="", "", 0) -> 0 | M2: =IF($A2="", "", G2) -> 11475.41 | N2: =IFERROR(IF($A2="", "", J2-K2), 0) -> 85100 | O2: =IFERROR(IF($A2="", "", MIN(G2,N2)), 0) -> 11475.41 | P2: =IFERROR(IF($A2="", "", MIN(G2+L2/PPYA,N2)*F2 + MAX(0, MIN(G2+L2/PPYA,N2) - MIN(G2,N2))), 0) -> 4475.4098 | Q2: =IFERROR(IF($A2="", "", K2+MIN(G2+L2/PPYA,N2)), 0) -> 11475.41 | R2: =IFERROR(IF($A2="", "", L2+P2), 0) -> 4475.4098 | S2: =IFERROR(IF($A2="","",P2),0) -> 4475.4098 | T2: =IF($A2="", "", LoanTerm + INT(($A2-1)/PPYA)) -> 12
A3: =IF(ROW()-1 <= TotalPeriodsA, ROW()-1, "") -> 2 | B3: =IF(ROW()-1 <= TotalPeriodsA, YEAR(StartYear) + INT((ROW()-2)/PPYA), "") -> 2027 | C3: =IF($A3="", "", MOD($A3-1, PPYA)+1) -> 2 | D3: =IF($A3="", "", C3=PPYA) -> FALSE | E3: =IF($A3="","",IncA*(1+Inflation)^((B3 - YEAR(StartYear)))) -> 145000 | F3: {=IF($A3="", "", MRate(E3))} -> 0.39 | G3: =IF($A3="", "", AfterTaxA/(1-F3)) -> 11475.41 | H3: =IF($A3="", "", _xlfn.XLOOKUP($B3, YearlyParamsA!$A:$A, YearlyParamsA!$E:$E, 0)) -> 70000 | I3: =IF($A3="", "", E3*SGRate) -> 17400 | J3: =IFERROR(IF($A3="", "", _xlfn.XLOOKUP($B3, YearlyParamsA!$A:$A, YearlyParamsA!$I:$I, 0)), 0) -> 85100 | K3: =IFERROR(IF($A2="", "", IF(B3<>B2,0,Q2)), 0) -> 11475.41 | L3: =IFERROR(IF($A2="","",IF(B3<>B2, 0, L2 + MIN(G2+L2/PPYA, J2-K2)*F2)), 0) -> 4475.4098 | M3: =IF($A3="", "", G3) -> 11475.41 | N3: =IFERROR(IF($A3="", "", J3-K3), 0) -> 73624.59 | O3: =IFERROR(IF($A3="", "", MIN(G3,N3)), 0) -> 11475.41 | P3: =IFERROR(IF($A3="", "", MIN(G3+L3/PPYA,N3)*F3 + MAX(0, MIN(G3+L3/PPYA,N3) - MIN(G3,N3))), 0) -> 4993.8115 | Q3: =IFERROR(IF($A3="", "", K3+MIN(G3+L3/PPYA,N3)), 0) -> 23323.77 | R3: =IFERROR(IF($A2="", "", IF(B3<>B2,P3,R2+P3)), 0) -> 9469.2213 | S3: =IFERROR(IF($A3="", "", S2+P3), 0) -> 9469.2213 | V3: PeriodsPerYear | W3: =_xlfn.XLOOKUP(FreqA,FreqLookup[Frequency],FreqLookup[PeriodsPerYear]) -> 12
A4: =IF(ROW()-1 <= TotalPeriodsA, ROW()-1, "") -> 3 | B4: =IF(ROW()-1 <= TotalPeriodsA, YEAR(StartYear) + INT((ROW()-2)/PPYA), "") -> 2027 | C4: =IF($A4="", "", MOD($A4-1, PPYA)+1) -> 3 | D4: =IF($A4="", "", C4=PPYA) -> FALSE | E4: =IF($A4="","",IncA*(1+Inflation)^((B4 - YEAR(StartYear)))) -> 145000 | F4: {=IF($A4="", "", MRate(E4))} -> 0.39 | G4: =IF($A4="", "", AfterTaxA/(1-F4)) -> 11475.41 | H4: =IF($A4="", "", _xlfn.XLOOKUP($B4, YearlyParamsA!$A:$A, YearlyParamsA!$E:$E, 0)) -> 70000 | I4: =IF($A4="", "", E4*SGRate) -> 17400 | J4: =IFERROR(IF($A4="", "", _xlfn.XLOOKUP($B4, YearlyParamsA!$A:$A, YearlyParamsA!$I:$I, 0)), 0) -> 85100 | K4: =IFERROR(IF($A3="", "", IF(B4<>B3,0,Q3)), 0) -> 23323.77 | L4: =IFERROR(IF($A3="","",IF(B4<>B3, 0, L3 + MIN(G3+L3/PPYA, J3-K3)*F3)), 0) -> 9096.2705 | M4: =IF($A4="", "", G4) -> 11475.41 | N4: =IFERROR(IF($A4="", "", J4-K4), 0) -> 61776.23 | O4: =IFERROR(IF($A4="", "", MIN(G4,N4)), 0) -> 11475.41 | P4: =IFERROR(IF($A4="", "", MIN(G4+L4/PPYA,N4)*F4 + MAX(0, MIN(G4+L4/PPYA,N4) - MIN(G4,N4))), 0) -> 5529.0612 | Q4: =IFERROR(IF($A4="", "", K4+MIN(G4+L4/PPYA,N4)), 0) -> 35557.203 | R4: =IFERROR(IF($A3="", "", IF(B4<>B3,P4,R3+P4)), 0) -> 14998.282 | S4: =IFERROR(IF($A4="", "", S3+P4), 0) -> 14998.282 | V4: TotalPeriods | W4: =ProjYearsA*PPYA -> 144
A5: =IF(ROW()-1 <= TotalPeriodsA, ROW()-1, "") -> 4 | B5: =IF(ROW()-1 <= TotalPeriodsA, YEAR(StartYear) + INT((ROW()-2)/PPYA), "") -> 2027 | C5: =IF($A5="", "", MOD($A5-1, PPYA)+1) -> 4 | D5: =IF($A5="", "", C5=PPYA) -> FALSE | E5: =IF($A5="","",IncA*(1+Inflation)^((B5 - YEAR(StartYear)))) -> 145000 | F5: {=IF($A5="", "", MRate(E5))} -> 0.39 | G5: =IF($A5="", "", AfterTaxA/(1-F5)) -> 11475.41 | H5: =IF($A5="", "", _xlfn.XLOOKUP($B5, YearlyParamsA!$A:$A, YearlyParamsA!$E:$E, 0)) -> 70000 | I5: =IF($A5="", "", E5*SGRate) -> 17400 | J5: =IFERROR(IF($A5="", "", _xlfn.XLOOKUP($B5, YearlyParamsA!$A:$A, YearlyParamsA!$I:$I, 0)), 0) -> 85100 | K5: =IFERROR(IF($A4="", "", IF(B5<>B4,0,Q4)), 0) -> 35557.203 | L5: =IFERROR(IF($A4="","",IF(B5<>B4, 0, L4 + MIN(G4+L4/PPYA, J4-K4)*F4)), 0) -> 13867.309 | M5: =IF($A5="", "", G5) -> 11475.41 | N5: =IFERROR(IF($A5="", "", J5-K5), 0) -> 49542.797 | O5: =IFERROR(IF($A5="", "", MIN(G5,N5)), 0) -> 11475.41 | P5: =IFERROR(IF($A5="", "", MIN(G5+L5/PPYA,N5)*F5 + MAX(0, MIN(G5+L5/PPYA,N5) - MIN(G5,N5))), 0) -> 6081.7065 | Q5: =IFERROR(IF($A5="", "", K5+MIN(G5+L5/PPYA,N5)), 0) -> 48188.222 | R5: =IFERROR(IF($A4="", "", IF(B5<>B4,P5,R4+P5)), 0) -> 21079.989 | S5: =IFERROR(IF($A5="", "", S4+P5), 0) -> 21079.989
A6: =IF(ROW()-1 <= TotalPeriodsA, ROW()-1, "") -> 5 | B6: =IF(ROW()-1 <= TotalPeriodsA, YEAR(StartYear) + INT((ROW()-2)/PPYA), "") -> 2027 | C6: =IF($A6="", "", MOD($A6-1, PPYA)+1) -> 5 | D6: =IF($A6="", "", C6=PPYA) -> FALSE | E6: =IF($A6="","",IncA*(1+Inflation)^((B6 - YEAR(StartYear)))) -> 145000 | F6: {=IF($A6="", "", MRate(E6))} -> 0.39 | G6: =IF($A6="", "", AfterTaxA/(1-F6)) -> 11475.41 | H6: =IF($A6="", "", _xlfn.XLOOKUP($B6, YearlyParamsA!$A:$A, YearlyParamsA!$E:$E, 0)) -> 70000 | I6: =IF($A6="", "", E6*SGRate) -> 17400 | J6: =IFERROR(IF($A6="", "", _xlfn.XLOOKUP($B6, YearlyParamsA!$A:$A, YearlyParamsA!$I:$I, 0)), 0) -> 85100 | K6: =IFERROR(IF($A5="", "", IF(B6<>B5,0,Q5)), 0) -> 48188.222 | L6: =IFERROR(IF($A5="","",IF(B6<>B5, 0, L5 + MIN(G5+L5/PPYA, J5-K5)*F5)), 0) -> 18793.407 | M6: =IF($A6="", "", G6) -> 11475.41 | N6: =IFERROR(IF($A6="", "", J6-K6), 0) -> 36911.778 | O6: =IFERROR(IF($A6="", "", MIN(G6,N6)), 0) -> 11475.41 | P6: =IFERROR(IF($A6="", "", MIN(G6+L6/PPYA,N6)*F6 + MAX(0, MIN(G6+L6/PPYA,N6) - MIN(G6,N6))), 0) -> 6652.3128 | Q6: =IFERROR(IF($A6="", "", K6+MIN(G6+L6/PPYA,N6)), 0) -> 61229.749 | R6: =IFERROR(IF($A5="", "", IF(B6<>B5,P6,R5+P6)), 0) -> 27732.302 | S6: =IFERROR(IF($A6="", "", S5+P6), 0) -> 27732.302
A7: =IF(ROW()-1 <= TotalPeriodsA, ROW()-1, "") -> 6 | B7: =IF(ROW()-1 <= TotalPeriodsA, YEAR(StartYear) + INT((ROW()-2)/PPYA), "") -> 2027 | C7: =IF($A7="", "", MOD($A7-1, PPYA)+1) -> 6 | D7: =IF($A7="", "", C7=PPYA) -> FALSE | E7: =IF($A7="","",IncA*(1+Inflation)^((B7 - YEAR(StartYear)))) -> 145000 | F7: {=IF($A7="", "", MRate(E7))} -> 0.39 | G7: =IF($A7="", "", AfterTaxA/(1-F7)) -> 11475.41 | H7: =IF($A7="", "", _xlfn.XLOOKUP($B7, YearlyParamsA!$A:$A, YearlyParamsA!$E:$E, 0)) -> 70000 | I7: =IF($A7="", "", E7*SGRate) -> 17400 | J7: =IFERROR(IF($A7="", "", _xlfn.XLOOKUP($B7, YearlyParamsA!$A:$A, YearlyParamsA!$I:$I, 0)), 0) -> 85100 | K7: =IFERROR(IF($A6="", "", IF(B7<>B6,0,Q6)), 0) -> 61229.749 | L7: =IFERROR(IF($A6="","",IF(B7<>B6, 0, L6 + MIN(G6+L6/PPYA, J6-K6)*F6)), 0) -> 23879.602 | M7: =IF($A7="", "", G7) -> 11475.41 | N7: =IFERROR(IF($A7="", "", J7-K7), 0) -> 23870.251 | O7: =IFERROR(IF($A7="", "", MIN(G7,N7)), 0) -> 11475.41 | P7: =IFERROR(IF($A7="", "", MIN(G7+L7/PPYA,N7)*F7 + MAX(0, MIN(G7+L7/PPYA,N7) - MIN(G7,N7))), 0) -> 7241.4637 | Q7: =IFERROR(IF($A7="", "", K7+MIN(G7+L7/PPYA,N7)), 0) -> 74695.126 | R7: =IFERROR(IF($A6="", "", IF(B7<>B6,P7,R6+P7)), 0) -> 34973.765 | S7: =IFERROR(IF($A7="", "", S6+P7), 0) -> 34973.765
A8: =IF(ROW()-1 <= TotalPeriodsA, ROW()-1, "") -> 7 | B8: =IF(ROW()-1 <= TotalPeriodsA, YEAR(StartYear) + INT((ROW()-2)/PPYA), "") -> 2027 | C8: =IF($A8="", "", MOD($A8-1, PPYA)+1) -> 7 | D8: =IF($A8="", "", C8=PPYA) -> FALSE | E8: =IF($A8="","",IncA*(1+Inflation)^((B8 - YEAR(StartYear)))) -> 145000 | F8: {=IF($A8="", "", MRate(E8))} -> 0.39 | G8: =IF($A8="", "", AfterTaxA/(1-F8)) -> 11475.41 | H8: =IF($A8="", "", _xlfn.XLOOKUP($B8, YearlyParamsA!$A:$A, YearlyParamsA!$E:$E, 0)) -> 70000 | I8: =IF($A8="", "", E8*SGRate) -> 17400 | J8: =IFERROR(IF($A8="", "", _xlfn.XLOOKUP($B8, YearlyParamsA!$A:$A, YearlyParamsA!$I:$I, 0)), 0) -> 85100 | K8: =IFERROR(IF($A7="", "", IF(B8<>B7,0,Q7)), 0) -> 74695.126 | L8: =IFERROR(IF($A7="","",IF(B8<>B7, 0, L7 + MIN(G7+L7/PPYA, J7-K7)*F7)), 0) -> 29131.099 | M8: =IF($A8="", "", G8) -> 11475.41 | N8: =IFERROR(IF($A8="", "", J8-K8), 0) -> 10404.874 | O8: =IFERROR(IF($A8="", "", MIN(G8,N8)), 0) -> 10404.874 | P8: =IFERROR(IF($A8="", "", MIN(G8+L8/PPYA,N8)*F8 + MAX(0, MIN(G8+L8/PPYA,N8) - MIN(G8,N8))), 0) -> 4057.901 | Q8: =IFERROR(IF($A8="", "", K8+MIN(G8+L8/PPYA,N8)), 0) -> 85100 | R8: =IFERROR(IF($A7="", "", IF(B8<>B7,P8,R7+P8)), 0) -> 39031.666 | S8: =IFERROR(IF($A8="", "", S7+P8), 0) -> 39031.666
A9: =IF(ROW()-1 <= TotalPeriodsA, ROW()-1, "") -> 8 | B9: =IF(ROW()-1 <= TotalPeriodsA, YEAR(StartYear) + INT((ROW()-2)/PPYA), "") -> 2027 | C9: =IF($A9="", "", MOD($A9-1, PPYA)+1) -> 8 | D9: =IF($A9="", "", C9=PPYA) -> FALSE | E9: =IF($A9="","",IncA*(1+Inflation)^((B9 - YEAR(StartYear)))) -> 145000 | F9: {=IF($A9="", "", MRate(E9))} -> 0.39 | G9: =IF($A9="", "", AfterTaxA/(1-F9)) -> 11475.41 | H9: =IF($A9="", "", _xlfn.XLOOKUP($B9, YearlyParamsA!$A:$A, YearlyParamsA!$E:$E, 0)) -> 70000 | I9: =IF($A9="", "", E9*SGRate) -> 17400 | J9: =IFERROR(IF($A9="", "", _xlfn.XLOOKUP($B9, YearlyParamsA!$A:$A, YearlyParamsA!$I:$I, 0)), 0) -> 85100 | K9: =IFERROR(IF($A8="", "", IF(B9<>B8,0,Q8)), 0) -> 85100 | L9: =IFERROR(IF($A8="","",IF(B9<>B8, 0, L8 + MIN(G8+L8/PPYA, J8-K8)*F8)), 0) -> 33189 | M9: =IF($A9="", "", G9) -> 11475.41 | N9: =IFERROR(IF($A9="", "", J9-K9), 0) -> 0 | O9: =IFERROR(IF($A9="", "", MIN(G9,N9)), 0) -> 0 | P9: =IFERROR(IF($A9="", "", MIN(G9+L9/PPYA,N9)*F9 + MAX(0, MIN(G9+L9/PPYA,N9) - MIN(G9,N9))), 0) -> 0 | Q9: =IFERROR(IF($A9="", "", K9+MIN(G9+L9/PPYA,N9)), 0) -> 85100 | R9: =IFERROR(IF($A8="", "", IF(B9<>B8,P9,R8+P9)), 0) -> 39031.666 | S9: =IFERROR(IF($A9="", "", S8+P9), 0) -> 39031.666
A10: =IF(ROW()-1 <= TotalPeriodsA, ROW()-1, "") -> 9 | B10: =IF(ROW()-1 <= TotalPeriodsA, YEAR(StartYear) + INT((ROW()-2)/PPYA), "") -> 2027 | C10: =IF($A10="", "", MOD($A10-1, PPYA)+1) -> 9 | D10: =IF($A10="", "", C10=PPYA) -> FALSE | E10: =IF($A10="","",IncA*(1+Inflation)^((B10 - YEAR(StartYear)))) -> 145000 | F10: {=IF($A10="", "", MRate(E10))} -> 0.39 | G10: =IF($A10="", "", AfterTaxA/(1-F10)) -> 11475.41 | H10: =IF($A10="", "", _xlfn.XLOOKUP($B10, YearlyParamsA!$A:$A, YearlyParamsA!$E:$E, 0)) -> 70000 | I10: =IF($A10="", "", E10*SGRate) -> 17400 | J10: =IFERROR(IF($A10="", "", _xlfn.XLOOKUP($B10, YearlyParamsA!$A:$A, YearlyParamsA!$I:$I, 0)), 0) -> 85100 | K10: =IFERROR(IF($A9="", "", IF(B10<>B9,0,Q9)), 0) -> 85100 | L10: =IFERROR(IF($A9="","",IF(B10<>B9, 0, L9 + MIN(G9+L9/PPYA, J9-K9)*F9)), 0) -> 33189 | M10: =IF($A10="", "", G10) -> 11475.41 | N10: =IFERROR(IF($A10="", "", J10-K10), 0) -> 0 | O10: =IFERROR(IF($A10="", "", MIN(G10,N10)), 0) -> 0 | P10: =IFERROR(IF($A10="", "", MIN(G10+L10/PPYA,N10)*F10 + MAX(0, MIN(G10+L10/PPYA,N10) - MIN(G10,N10))), 0) -> 0 | Q10: =IFERROR(IF($A10="", "", K10+MIN(G10+L10/PPYA,N10)), 0) -> 85100 | R10: =IFERROR(IF($A9="", "", IF(B10<>B9,P10,R9+P10)), 0) -> 39031.666 | S10: =IFERROR(IF($A10="", "", S9+P10), 0) -> 39031.666
A11: =IF(ROW()-1 <= TotalPeriodsA, ROW()-1, "") -> 10 | B11: =IF(ROW()-1 <= TotalPeriodsA, YEAR(StartYear) + INT((ROW()-2)/PPYA), "") -> 2027 | C11: =IF($A11="", "", MOD($A11-1, PPYA)+1) -> 10 | D11: =IF($A11="", "", C11=PPYA) -> FALSE | E11: =IF($A11="","",IncA*(1+Inflation)^((B11 - YEAR(StartYear)))) -> 145000 | F11: {=IF($A11="", "", MRate(E11))} -> 0.39 | G11: =IF($A11="", "", AfterTaxA/(1-F11)) -> 11475.41 | H11: =IF($A11="", "", _xlfn.XLOOKUP($B11, YearlyParamsA!$A:$A, YearlyParamsA!$E:$E, 0)) -> 70000 | I11: =IF($A11="", "", E11*SGRate) -> 17400 | J11: =IFERROR(IF($A11="", "", _xlfn.XLOOKUP($B11, YearlyParamsA!$A:$A, YearlyParamsA!$I:$I, 0)), 0) -> 85100 | K11: =IFERROR(IF($A10="", "", IF(B11<>B10,0,Q10)), 0) -> 85100 | L11: =IFERROR(IF($A10="","",IF(B11<>B10, 0, L10 + MIN(G10+L10/PPYA, J10-K10)*F10)), 0) -> 33189 | M11: =IF($A11="", "", G11) -> 11475.41 | N11: =IFERROR(IF($A11="", "", J11-K11), 0) -> 0 | O11: =IFERROR(IF($A11="", "", MIN(G11,N11)), 0) -> 0 | P11: =IFERROR(IF($A11="", "", MIN(G11+L11/PPYA,N11)*F11 + MAX(0, MIN(G11+L11/PPYA,N11) - MIN(G11,N11))), 0) -> 0 | Q11: =IFERROR(IF($A11="", "", K11+MIN(G11+L11/PPYA,N11)), 0) -> 85100 | R11: =IFERROR(IF($A10="", "", IF(B11<>B10,P11,R10+P11)), 0) -> 39031.666 | S11: =IFERROR(IF($A11="", "", S10+P11), 0) -> 39031.666
A12: =IF(ROW()-1 <= TotalPeriodsA, ROW()-1, "") -> 11 | B12: =IF(ROW()-1 <= TotalPeriodsA, YEAR(StartYear) + INT((ROW()-2)/PPYA), "") -> 2027 | C12: =IF($A12="", "", MOD($A12-1, PPYA)+1) -> 11 | D12: =IF($A12="", "", C12=PPYA) -> FALSE | E12: =IF($A12="","",IncA*(1+Inflation)^((B12 - YEAR(StartYear)))) -> 145000 | F12: {=IF($A12="", "", MRate(E12))} -> 0.39 | G12: =IF($A12="", "", AfterTaxA/(1-F12)) -> 11475.41 | H12: =IF($A12="", "", _xlfn.XLOOKUP($B12, YearlyParamsA!$A:$A, YearlyParamsA!$E:$E, 0)) -> 70000 | I12: =IF($A12="", "", E12*SGRate) -> 17400 | J12: =IFERROR(IF($A12="", "", _xlfn.XLOOKUP($B12, YearlyParamsA!$A:$A, YearlyParamsA!$I:$I, 0)), 0) -> 85100 | K12: =IFERROR(IF($A11="", "", IF(B12<>B11,0,Q11)), 0) -> 85100 | L12: =IFERROR(IF($A11="","",IF(B12<>B11, 0, L11 + MIN(G11+L11/PPYA, J11-K11)*F11)), 0) -> 33189 | M12: =IF($A12="", "", G12) -> 11475.41 | N12: =IFERROR(IF($A12="", "", J12-K12), 0) -> 0 | O12: =IFERROR(IF($A12="", "", MIN(G12,N12)), 0) -> 0 | P12: =IFERROR(IF($A12="", "", MIN(G12+L12/PPYA,N12)*F12 + MAX(0, MIN(G12+L12/PPYA,N12) - MIN(G12,N12))), 0) -> 0 | Q12: =IFERROR(IF($A12="", "", K12+MIN(G12+L12/PPYA,N12)), 0) -> 85100 | R12: =IFERROR(IF($A11="", "", IF(B12<>B11,P12,R11+P12)), 0) -> 39031.666 | S12: =IFERROR(IF($A12="", "", S11+P12), 0) -> 39031.666
A13: =IF(ROW()-1 <= TotalPeriodsA, ROW()-1, "") -> 12 | B13: =IF(ROW()-1 <= TotalPeriodsA, YEAR(StartYear) + INT((ROW()-2)/PPYA), "") -> 2027 | C13: =IF($A13="", "", MOD($A13-1, PPYA)+1) -> 12 | D13: =IF($A13="", "", C13=PPYA) -> TRUE | E13: =IF($A13="","",IncA*(1+Inflation)^((B13 - YEAR(StartYear)))) -> 145000 | F13: {=IF($A13="", "", MRate(E13))} -> 0.39 | G13: =IF($A13="", "", AfterTaxA/(1-F13)) -> 11475.41 | H13: =IF($A13="", "", _xlfn.XLOOKUP($B13, YearlyParamsA!$A:$A, YearlyParamsA!$E:$E, 0)) -> 70000 | I13: =IF($A13="", "", E13*SGRate) -> 17400 | J13: =IFERROR(IF($A13="", "", _xlfn.XLOOKUP($B13, YearlyParamsA!$A:$A, YearlyParamsA!$I:$I, 0)), 0) -> 85100 | K13: =IFERROR(IF($A12="", "", IF(B13<>B12,0,Q12)), 0) -> 85100 | L13: =IFERROR(IF($A12="","",IF(B13<>B12, 0, L12 + MIN(G12+L12/PPYA, J12-K12)*F12)), 0) -> 33189 | M13: =IF($A13="", "", G13) -> 11475.41 | N13: =IFERROR(IF($A13="", "", J13-K13), 0) -> 0 | O13: =IFERROR(IF($A13="", "", MIN(G13,N13)), 0) -> 0 | P13: =IFERROR(IF($A13="", "", MIN(G13+L13/PPYA,N13)*F13 + MAX(0, MIN(G13+L13/PPYA,N13) - MIN(G13,N13))), 0) -> 0 | Q13: =IFERROR(IF($A13="", "", K13+MIN(G13+L13/PPYA,N13)), 0) -> 85100 | R13: =IFERROR(IF($A12="", "", IF(B13<>B12,P13,R12+P13)), 0) -> 39031.666 | S13: =IFERROR(IF($A13="", "", S12+P13), 0) -> 39031.666
A14: =IF(ROW()-1 <= TotalPeriodsA, ROW()-1, "") -> 13 | B14: =IF(ROW()-1 <= TotalPeriodsA, YEAR(StartYear) + INT((ROW()-2)/PPYA), "") -> 2028 | C14: =IF($A14="", "", MOD($A14-1, PPYA)+1) -> 1 | D14: =IF($A14="", "", C14=PPYA) -> FALSE | E14: =IF($A14="","",IncA*(1+Inflation)^((B14 - YEAR(StartYear)))) -> 148625 | F14: {=IF($A14="", "", MRate(E14))} -> 0.39 | G14: =IF($A14="", "", AfterTaxA/(1-F14)) -> 11475.41 | H14: =IF($A14="", "", _xlfn.XLOOKUP($B14, YearlyParamsA!$A:$A, YearlyParamsA!$E:$E, 0)) -> 0 | I14: =IF($A14="", "", E14*SGRate) -> 17835 | J14: =IFERROR(IF($A14="", "", _xlfn.XLOOKUP($B14, YearlyParamsA!$A:$A, YearlyParamsA!$I:$I, 0)), 0) -> 14665 | K14: =IFERROR(IF($A13="", "", IF(B14<>B13,0,Q13)), 0) -> 0 | L14: =IFERROR(IF($A13="","",IF(B14<>B13, 0, L13 + MIN(G13+L13/PPYA, J13-K13)*F13)), 0) -> 0 | M14: =IF($A14="", "", G14) -> 11475.41 | N14: =IFERROR(IF($A14="", "", J14-K14), 0) -> 14665 | O14: =IFERROR(IF($A14="", "", MIN(G14,N14)), 0) -> 11475.41 | P14: =IFERROR(IF($A14="", "", MIN(G14+L14/PPYA,N14)*F14 + MAX(0, MIN(G14+L14/PPYA,N14) - MIN(G14,N14))), 0) -> 4475.4098 | Q14: =IFERROR(IF($A14="", "", K14+MIN(G14+L14/PPYA,N14)), 0) -> 11475.41 | R14: =IFERROR(IF($A13="", "", IF(B14<>B13,P14,R13+P14)), 0) -> 4475.4098 | S14: =IFERROR(IF($A14="", "", S13+P14), 0) -> 43507.076
A15: =IF(ROW()-1 <= TotalPeriodsA, ROW()-1, "") -> 14 | B15: =IF(ROW()-1 <= TotalPeriodsA, YEAR(StartYear) + INT((ROW()-2)/PPYA), "") -> 2028 | C15: =IF($A15="", "", MOD($A15-1, PPYA)+1) -> 2 | D15: =IF($A15="", "", C15=PPYA) -> FALSE | E15: =IF($A15="","",IncA*(1+Inflation)^((B15 - YEAR(StartYear)))) -> 148625 | F15: {=IF($A15="", "", MRate(E15))} -> 0.39 | G15: =IF($A15="", "", AfterTaxA/(1-F15)) -> 11475.41 | H15: =IF($A15="", "", _xlfn.XLOOKUP($B15, YearlyParamsA!$A:$A, YearlyParamsA!$E:$E, 0)) -> 0 | I15: =IF($A15="", "", E15*SGRate) -> 17835 | J15: =IFERROR(IF($A15="", "", _xlfn.XLOOKUP($B15, YearlyParamsA!$A:$A, YearlyParamsA!$I:$I, 0)), 0) -> 14665 | K15: =IFERROR(IF($A14="", "", IF(B15<>B14,0,Q14)), 0) -> 11475.41 | L15: =IFERROR(IF($A14="","",IF(B15<>B14, 0, L14 + MIN(G14+L14/PPYA, J14-K14)*F14)), 0) -> 4475.4098 | M15: =IF($A15="", "", G15) -> 11475.41 | N15: =IFERROR(IF($A15="", "", J15-K15), 0) -> 3189.5902 | O15: =IFERROR(IF($A15="", "", MIN(G15,N15)), 0) -> 3189.5902 | P15: =IFERROR(IF($A15="", "", MIN(G15+L15/PPYA,N15)*F15 + MAX(0, MIN(G15+L15/PPYA,N15) - MIN(G15,N15))), 0) -> 1243.9402 | Q15: =IFERROR(IF($A15="", "", K15+MIN(G15+L15/PPYA,N15)), 0) -> 14665 | R15: =IFERROR(IF($A14="", "", IF(B15<>B14,P15,R14+P15)), 0) -> 5719.35 | S15: =IFERROR(IF($A15="", "", S14+P15), 0) -> 44751.016
A16: =IF(ROW()-1 <= TotalPeriodsA, ROW()-1, "") -> 15 | B16: =IF(ROW()-1 <= TotalPeriodsA, YEAR(StartYear) + INT((ROW()-2)/PPYA), "") -> 2028 | C16: =IF($A16="", "", MOD($A16-1, PPYA)+1) -> 3 | D16: =IF($A16="", "", C16=PPYA) -> FALSE | E16: =IF($A16="","",IncA*(1+Inflation)^((B16 - YEAR(StartYear)))) -> 148625 | F16: {=IF($A16="", "", MRate(E16))} -> 0.39 | G16: =IF($A16="", "", AfterTaxA/(1-F16)) -> 11475.41 | H16: =IF($A16="", "", _xlfn.XLOOKUP($B16, YearlyParamsA!$A:$A, YearlyParamsA!$E:$E, 0)) -> 0 | I16: =IF($A16="", "", E16*SGRate) -> 17835 | J16: =IFERROR(IF($A16="", "", _xlfn.XLOOKUP($B16, YearlyParamsA!$A:$A, YearlyParamsA!$I:$I, 0)), 0) -> 14665 | K16: =IFERROR(IF($A15="", "", IF(B16<>B15,0,Q15)), 0) -> 14665 | L16: =IFERROR(IF($A15="","",IF(B16<>B15, 0, L15 + MIN(G15+L15/PPYA, J15-K15)*F15)), 0) -> 5719.35 | M16: =IF($A16="", "", G16) -> 11475.41 | N16: =IFERROR(IF($A16="", "", J16-K16), 0) -> 0 | O16: =IFERROR(IF($A16="", "", MIN(G16,N16)), 0) -> 0 | P16: =IFERROR(IF($A16="", "", MIN(G16+L16/PPYA,N16)*F16 + MAX(0, MIN(G16+L16/PPYA,N16) - MIN(G16,N16))), 0) -> 0 | Q16: =IFERROR(IF($A16="", "", K16+MIN(G16+L16/PPYA,N16)), 0) -> 14665 | R16: =IFERROR(IF($A15="", "", IF(B16<>B15,P16,R15+P16)), 0) -> 5719.35 | S16: =IFERROR(IF($A16="", "", S15+P16), 0) -> 44751.016
... A145: =IF(ROW()-1 <= TotalPeriodsA, ROW()-1, "") -> 144 | B145: =IF(ROW()-1 <= TotalPeriodsA, YEAR(StartYear) + INT((ROW()-2)/PPYA), "") -> 2038 | C145: =IF($A145="", "", MOD($A145-1, PPYA)+1) -> 12 | D145: =IF($A145="", "", C145=PPYA) -> TRUE | E145: =IF($A145="","",IncA*(1+Inflation)^((B145 - YEAR(StartYear)))) -> 190252.57 | F145: {=IF($A145="", "", MRate(E145))} -> 0.47 | G145: =IF($A145="", "", AfterTaxA/(1-F145)) -> 13207.547 | H145: =IF($A145="", "", _xlfn.XLOOKUP($B145, YearlyParamsA!$A:$A, YearlyParamsA!$E:$E, 0)) -> 0 | I145: =IF($A145="", "", E145*SGRate) -> 22830.308 | J145: =IFERROR(IF($A145="", "", _xlfn.XLOOKUP($B145, YearlyParamsA!$A:$A, YearlyParamsA!$I:$I, 0)), 0) -> 22169.692 | K145: =IFERROR(IF($A144="", "", IF(B145<>B144,0,Q144)), 0) -> 22169.692 | L145: =IFERROR(IF($A144="","",IF(B145<>B144, 0, L144 + MIN(G144+L144/PPYA, J144-K144)*F144)), 0) -> 10419.755 | M145: =IF($A145="", "", G145) -> 13207.547 | N145: =IFERROR(IF($A145="", "", J145-K145), 0) -> 0 | O145: =IFERROR(IF($A145="", "", MIN(G145,N145)), 0) -> 0 | P145: =IFERROR(IF($A145="", "", MIN(G145+L145/PPYA,N145)*F145 + MAX(0, MIN(G145+L145/PPYA,N145) - MIN(G145,N145))), 0) -> 0 | Q145: =IFERROR(IF($A145="", "", K145+MIN(G145+L145/PPYA,N145)), 0) -> 22169.692 | R145: =IFERROR(IF($A144="", "", IF(B145<>B144,P145,R144+P145)), 0) -> 10419.755 | S145: =IFERROR(IF($A145="", "", S144+P145), 0) -> 122649.62

Sheet PersonaB
A1: Period | B1: Year | C1: PeriodInYear | D1: IsSweepPeriod | E1: AnnualIncome | F1: MarginalRate | G1: BasePreTax | H1: CarryFwdThisYear | I1: EmployerSGAnnual | J1: AllowablePersonalAnnual | K1: CumulativePrev | L1: TaxSavedPrev | M1: ClientPreTaxContrib | N1: AvailableRoom | O1: ClientContribution | P1: TotalTaxBenefit | Q1: CumulativeSuperYTD | R1: CumulativeTaxSavedYTD | S1: CumulativeTaxSavedTotal | T1: LoanTermAdj
A2: =IF(ROW()-1 <= TotalPeriodsB, ROW()-1, "") -> 1 | B2: =IF(ROW()-1 <= TotalPeriodsB, YEAR(StartYear) + INT((ROW()-2)/PPYB), "") -> 2027 | C2: =IF($A2="", "", MOD($A2-1, PPYB)+1) -> 1 | D2: =IF($A2="", "", C2=PPYB) -> FALSE | E2: =IF($A2="","",IncB*(1+Inflation)^((B2 - YEAR(StartYear)))) -> 230000 | F2: {=IF($A2="", "", MRate(E2))} -> 0.47 | G2: =IF($A2="", "", AfterTaxB/(1-F2)) -> 9433.9623 | H2: =IF($A2="", "", _xlfn.XLOOKUP($B2, YearlyParamsB!$A:$A, YearlyParamsB!$E:$E, 0)) -> 120000 | I2: =IF($A2="", "", E2*SGRate) -> 27600 | J2: =IFERROR(IF($A2="", "", _xlfn.XLOOKUP($B2, YearlyParamsB!$A:$A, YearlyParamsB!$I:$I, 0)), 0) -> 124900 | K2: =IF($A2="", "", 0) -> 0 | L2: =IF($A2="", "", 0) -> 0 | M2: =IF($A2="", "", G2) -> 9433.9623 | N2: =IFERROR(IF($A2="", "", J2-K2), 0) -> 124900 | O2: =IFERROR(IF($A2="", "", MIN(G2,N2)), 0) -> 9433.9623 | P2: =IFERROR(IF($A2="", "", MIN(G2+L2/PPYB,N2)*F2 + MAX(0, MIN(G2+L2/PPYB,N2) - MIN(G2,N2))), 0) -> 4433.9623 | Q2: =IFERROR(IF($A2="", "", K2+MIN(G2+L2/PPYB,N2)), 0) -> 9433.9623 | R2: =IFERROR(IF($A2="", "", L2+P2), 0) -> 4433.9623 | S2: =IFERROR(IF($A2="","",P2),0) -> 4433.9623 | T2: =IF($A2="", "", LoanTerm + INT(($A2-1)/PPYB)) -> 12
A3: =IF(ROW()-1 <= TotalPeriodsB, ROW()-1, "") -> 2 | B3: =IF(ROW()-1 <= TotalPeriodsB, YEAR(StartYear) + INT((ROW()-2)/PPYB), "") -> 2027 | C3: =IF($A3="", "", MOD($A3-1, PPYB)+1) -> 2 | D3: =IF($A3="", "", C3=PPYB) -> FALSE | E3: =IF($A3="","",IncB*(1+Inflation)^((B3 - YEAR(StartYear)))) -> 230000 | F3: {=IF($A3="", "", MRate(E3))} -> 0.47 | G3: =IF($A3="", "", AfterTaxB/(1-F3)) -> 9433.9623 | H3: =IF($A3="", "", _xlfn.XLOOKUP($B3, YearlyParamsB!$A:$A, YearlyParamsB!$E:$E, 0)) -> 120000 | I3: =IF($A3="", "", E3*SGRate) -> 27600 | J3: =IFERROR(IF($A3="", "", _xlfn.XLOOKUP($B3, YearlyParamsB!$A:$A, YearlyParamsB!$I:$I, 0)), 0) -> 124900 | K3: =IFERROR(IF($A2="", "", IF(B3<>B2,0,Q2)), 0) -> 9433.9623 | L3: =IFERROR(IF($A2="","",IF(B3<>B2, 0, L2 + MIN(G2+L2/PPYB, J2-K2)*F2)), 0) -> 4433.9623 | M3: =IF($A3="", "", G3) -> 9433.9623 | N3: =IFERROR(IF($A3="", "", J3-K3), 0) -> 115466.04 | O3: =IFERROR(IF($A3="", "", MIN(G3,N3)), 0) -> 9433.9623 | P3: =IFERROR(IF($A3="", "", MIN(G3+L3/PPYB,N3)*F3 + MAX(0, MIN(G3+L3/PPYB,N3) - MIN(G3,N3))), 0) -> 4977.1226 | Q3: =IFERROR(IF($A3="", "", K3+MIN(G3+L3/PPYB,N3)), 0) -> 19237.421 | R3: =IFERROR(IF($A2="", "", IF(B3<>B2,P3,R2+P3)), 0) -> 9411.0849 | S3: =IFERROR(IF($A3="", "", S2+P3), 0) -> 9411.0849 | V3: PeriodsPerYear | W3: =_xlfn.XLOOKUP(FreqB,FreqLookup[Frequency],FreqLookup[PeriodsPerYear]) -> 12
A4: =IF(ROW()-1 <= TotalPeriodsB, ROW()-1, "") -> 3 | B4: =IF(ROW()-1 <= TotalPeriodsB, YEAR(StartYear) + INT((ROW()-2)/PPYB), "") -> 2027 | C4: =IF($A4="", "", MOD($A4-1, PPYB)+1) -> 3 | D4: =IF($A4="", "", C4=PPYB) -> FALSE | E4: =IF($A4="","",IncB*(1+Inflation)^((B4 - YEAR(StartYear)))) -> 230000 | F4: {=IF($A4="", "", MRate(E4))} -> 0.47 | G4: =IF($A4="", "", AfterTaxB/(1-F4)) -> 9433.9623 | H4: =IF($A4="", "", _xlfn.XLOOKUP($B4, YearlyParamsB!$A:$A, YearlyParamsB!$E:$E, 0)) -> 120000 | I4: =IF($A4="", "", E4*SGRate) -> 27600 | J4: =IFERROR(IF($A4="", "", _xlfn.XLOOKUP($B4, YearlyParamsB!$A:$A, YearlyParamsB!$I:$I, 0)), 0) -> 124900 | K4: =IFERROR(IF($A3="", "", IF(B4<>B3,0,Q3)), 0) -> 19237.421 | L4: =IFERROR(IF($A3="","",IF(B4<>B3, 0, L3 + MIN(G3+L3/PPYB, J3-K3)*F3)), 0) -> 9041.5881 | M4: =IF($A4="", "", G4) -> 9433.9623 | N4: =IFERROR(IF($A4="", "", J4-K4), 0) -> 105662.58 | O4: =IFERROR(IF($A4="", "", MIN(G4,N4)), 0) -> 9433.9623 | P4: =IFERROR(IF($A4="", "", MIN(G4+L4/PPYB,N4)*F4 + MAX(0, MIN(G4+L4/PPYB,N4) - MIN(G4,N4))), 0) -> 5541.5568 | Q4: =IFERROR(IF($A4="", "", K4+MIN(G4+L4/PPYB,N4)), 0) -> 29424.849 | R4: =IFERROR(IF($A3="", "", IF(B4<>B3,P4,R3+P4)), 0) -> 14952.642 | S4: =IFERROR(IF($A4="", "", S3+P4), 0) -> 14952.642 | V4: TotalPeriods | W4: =ProjYearsB*PPYB -> 180
A5: =IF(ROW()-1 <= TotalPeriodsB, ROW()-1, "") -> 4 | B5: =IF(ROW()-1 <= TotalPeriodsB, YEAR(StartYear) + INT((ROW()-2)/PPYB), "") -> 2027 | C5: =IF($A5="", "", MOD($A5-1, PPYB)+1) -> 4 | D5: =IF($A5="", "", C5=PPYB) -> FALSE | E5: =IF($A5="","",IncB*(1+Inflation)^((B5 - YEAR(StartYear)))) -> 230000 | F5: {=IF($A5="", "", MRate(E5))} -> 0.47 | G5: =IF($A5="", "", AfterTaxB/(1-F5)) -> 9433.9623 | H5: =IF($A5="", "", _xlfn.XLOOKUP($B5, YearlyParamsB!$A:$A, YearlyParamsB!$E:$E, 0)) -> 120000 | I5: =IF($A5="", "", E5*SGRate) -> 27600 | J5: =IFERROR(IF($A5="", "", _xlfn.XLOOKUP($B5, YearlyParamsB!$A:$A, YearlyParamsB!$I:$I, 0)), 0) -> 124900 | K5: =IFERROR(IF($A4="", "", IF(B5<>B4,0,Q4)), 0) -> 29424.849 | L5: =IFERROR(IF($A4="","",IF(B5<>B4, 0, L4 + MIN(G4+L4/PPYB, J4-K4)*F4)), 0) -> 13829.679 | M5: =IF($A5="", "", G5) -> 9433.9623 | N5: =IFERROR(IF($A5="", "", J5-K5), 0) -> 95475.151 | O5: =IFERROR(IF($A5="", "", MIN(G5,N5)), 0) -> 9433.9623 | P5: =IFERROR(IF($A5="", "", MIN(G5+L5/PPYB,N5)*F5 + MAX(0, MIN(G5+L5/PPYB,N5) - MIN(G5,N5))), 0) -> 6128.098 | Q5: =IFERROR(IF($A5="", "", K5+MIN(G5+L5/PPYB,N5)), 0) -> 40011.285 | R5: =IFERROR(IF($A4="", "", IF(B5<>B4,P5,R4+P5)), 0) -> 21080.74 | S5: =IFERROR(IF($A5="", "", S4+P5), 0) -> 21080.74
A6: =IF(ROW()-1 <= TotalPeriodsB, ROW()-1, "") -> 5 | B6: =IF(ROW()-1 <= TotalPeriodsB, YEAR(StartYear) + INT((ROW()-2)/PPYB), "") -> 2027 | C6: =IF($A6="", "", MOD($A6-1, PPYB)+1) -> 5 | D6: =IF($A6="", "", C6=PPYB) -> FALSE | E6: =IF($A6="","",IncB*(1+Inflation)^((B6 - YEAR(StartYear)))) -> 230000 | F6: {=IF($A6="", "", MRate(E6))} -> 0.47 | G6: =IF($A6="", "", AfterTaxB/(1-F6)) -> 9433.9623 | H6: =IF($A6="", "", _xlfn.XLOOKUP($B6, YearlyParamsB!$A:$A, YearlyParamsB!$E:$E, 0)) -> 120000 | I6: =IF($A6="", "", E6*SGRate) -> 27600 | J6: =IFERROR(IF($A6="", "", _xlfn.XLOOKUP($B6, YearlyParamsB!$A:$A, YearlyParamsB!$I:$I, 0)), 0) -> 124900 | K6: =IFERROR(IF($A5="", "", IF(B6<>B5,0,Q5)), 0) -> 40011.285 | L6: =IFERROR(IF($A5="","",IF(B6<>B5, 0, L5 + MIN(G5+L5/PPYB, J5-K5)*F5)), 0) -> 18805.304 | M6: =IF($A6="", "", G6) -> 9433.9623 | N6: =IFERROR(IF($A6="", "", J6-K6), 0) -> 84888.715 | O6: =IFERROR(IF($A6="", "", MIN(G6,N6)), 0) -> 9433.9623 | P6: =IFERROR(IF($A6="", "", MIN(G6+L6/PPYB,N6)*F6 + MAX(0, MIN(G6+L6/PPYB,N6) - MIN(G6,N6))), 0) -> 6737.612 | Q6: =IFERROR(IF($A6="", "", K6+MIN(G6+L6/PPYB,N6)), 0) -> 51012.356 | R6: =IFERROR(IF($A5="", "", IF(B6<>B5,P6,R5+P6)), 0) -> 27818.352 | S6: =IFERROR(IF($A6="", "", S5+P6), 0) -> 27818.352
A7: =IF(ROW()-1 <= TotalPeriodsB, ROW()-1, "") -> 6 | B7: =IF(ROW()-1 <= TotalPeriodsB, YEAR(StartYear) + INT((ROW()-2)/PPYB), "") -> 2027 | C7: =IF($A7="", "", MOD($A7-1, PPYB)+1) -> 6 | D7: =IF($A7="", "", C7=PPYB) -> FALSE | E7: =IF($A7="","",IncB*(1+Inflation)^((B7 - YEAR(StartYear)))) -> 230000 | F7: {=IF($A7="", "", MRate(E7))} -> 0.47 | G7: =IF($A7="", "", AfterTaxB/(1-F7)) -> 9433.9623 | H7: =IF($A7="", "", _xlfn.XLOOKUP($B7, YearlyParamsB!$A:$A, YearlyParamsB!$E:$E, 0)) -> 120000 | I7: =IF($A7="", "", E7*SGRate) -> 27600 | J7: =IFERROR(IF($A7="", "", _xlfn.XLOOKUP($B7, YearlyParamsB!$A:$A, YearlyParamsB!$I:$I, 0)), 0) -> 124900 | K7: =IFERROR(IF($A6="", "", IF(B7<>B6,0,Q6)), 0) -> 51012.356 | L7: =IFERROR(IF($A6="","",IF(B7<>B6, 0, L6 + MIN(G6+L6/PPYB, J6-K6)*F6)), 0) -> 23975.807 | M7: =IF($A7="", "", G7) -> 9433.9623 | N7: =IFERROR(IF($A7="", "", J7-K7), 0) -> 73887.644 | O7: =IFERROR(IF($A7="", "", MIN(G7,N7)), 0) -> 9433.9623 | P7: =IFERROR(IF($A7="", "", MIN(G7+L7/PPYB,N7)*F7 + MAX(0, MIN(G7+L7/PPYB,N7) - MIN(G7,N7))), 0) -> 7370.9986 | Q7: =IFERROR(IF($A7="", "", K7+MIN(G7+L7/PPYB,N7)), 0) -> 62444.302 | R7: =IFERROR(IF($A6="", "", IF(B7<>B6,P7,R6+P7)), 0) -> 35189.35 | S7: =IFERROR(IF($A7="", "", S6+P7), 0) -> 35189.35
A8: =IF(ROW()-1 <= TotalPeriodsB, ROW()-1, "") -> 7 | B8: =IF(ROW()-1 <= TotalPeriodsB, YEAR(StartYear) + INT((ROW()-2)/PPYB), "") -> 2027 | C8: =IF($A8="", "", MOD($A8-1, PPYB)+1) -> 7 | D8: =IF($A8="", "", C8=PPYB) -> FALSE | E8: =IF($A8="","",IncB*(1+Inflation)^((B8 - YEAR(StartYear)))) -> 230000 | F8: {=IF($A8="", "", MRate(E8))} -> 0.47 | G8: =IF($A8="", "", AfterTaxB/(1-F8)) -> 9433.9623 | H8: =IF($A8="", "", _xlfn.XLOOKUP($B8, YearlyParamsB!$A:$A, YearlyParamsB!$E:$E, 0)) -> 120000 | I8: =IF($A8="", "", E8*SGRate) -> 27600 | J8: =IFERROR(IF($A8="", "", _xlfn.XLOOKUP($B8, YearlyParamsB!$A:$A, YearlyParamsB!$I:$I, 0)), 0) -> 124900 | K8: =IFERROR(IF($A7="", "", IF(B8<>B7,0,Q7)), 0) -> 62444.302 | L8: =IFERROR(IF($A7="","",IF(B8<>B7, 0, L7 + MIN(G7+L7/PPYB, J7-K7)*F7)), 0) -> 29348.822 | M8: =IF($A8="", "", G8) -> 9433.9623 | N8: =IFERROR(IF($A8="", "", J8-K8), 0) -> 62455.698 | O8: =IFERROR(IF($A8="", "", MIN(G8,N8)), 0) -> 9433.9623 | P8: =IFERROR(IF($A8="", "", MIN(G8+L8/PPYB,N8)*F8 + MAX(0, MIN(G8+L8/PPYB,N8) - MIN(G8,N8))), 0) -> 8029.1929 | Q8: =IFERROR(IF($A8="", "", K8+MIN(G8+L8/PPYB,N8)), 0) -> 74323.999 | R8: =IFERROR(IF($A7="", "", IF(B8<>B7,P8,R7+P8)), 0) -> 43218.543 | S8: =IFERROR(IF($A8="", "", S7+P8), 0) -> 43218.543
A9: =IF(ROW()-1 <= TotalPeriodsB, ROW()-1, "") -> 8 | B9: =IF(ROW()-1 <= TotalPeriodsB, YEAR(StartYear) + INT((ROW()-2)/PPYB), "") -> 2027 | C9: =IF($A9="", "", MOD($A9-1, PPYB)+1) -> 8 | D9: =IF($A9="", "", C9=PPYB) -> FALSE | E9: =IF($A9="","",IncB*(1+Inflation)^((B9 - YEAR(StartYear)))) -> 230000 | F9: {=IF($A9="", "", MRate(E9))} -> 0.47 | G9: =IF($A9="", "", AfterTaxB/(1-F9)) -> 9433.9623 | H9: =IF($A9="", "", _xlfn.XLOOKUP($B9, YearlyParamsB!$A:$A, YearlyParamsB!$E:$E, 0)) -> 120000 | I9: =IF($A9="", "", E9*SGRate) -> 27600 | J9: =IFERROR(IF($A9="", "", _xlfn.XLOOKUP($B9, YearlyParamsB!$A:$A, YearlyParamsB!$I:$I, 0)), 0) -> 124900 | K9: =IFERROR(IF($A8="", "", IF(B9<>B8,0,Q8)), 0) -> 74323.999 | L9: =IFERROR(IF($A8="","",IF(B9<>B8, 0, L8 + MIN(G8+L8/PPYB, J8-K8)*F8)), 0) -> 34932.28 | M9: =IF($A9="", "", G9) -> 9433.9623 | N9: =IFERROR(IF($A9="", "", J9-K9), 0) -> 50576.001 | O9: =IFERROR(IF($A9="", "", MIN(G9,N9)), 0) -> 9433.9623 | P9: =IFERROR(IF($A9="", "", MIN(G9+L9/PPYB,N9)*F9 + MAX(0, MIN(G9+L9/PPYB,N9) - MIN(G9,N9))), 0) -> 8713.1665 | Q9: =IFERROR(IF($A9="", "", K9+MIN(G9+L9/PPYB,N9)), 0) -> 86668.985 | R9: =IFERROR(IF($A8="", "", IF(B9<>B8,P9,R8+P9)), 0) -> 51931.71 | S9: =IFERROR(IF($A9="", "", S8+P9), 0) -> 51931.71
A10: =IF(ROW()-1 <= TotalPeriodsB, ROW()-1, "") -> 9 | B10: =IF(ROW()-1 <= TotalPeriodsB, YEAR(StartYear) + INT((ROW()-2)/PPYB), "") -> 2027 | C10: =IF($A10="", "", MOD($A10-1, PPYB)+1) -> 9 | D10: =IF($A10="", "", C10=PPYB) -> FALSE | E10: =IF($A10="","",IncB*(1+Inflation)^((B10 - YEAR(StartYear)))) -> 230000 | F10: {=IF($A10="", "", MRate(E10))} -> 0.47 | G10: =IF($A10="", "", AfterTaxB/(1-F10)) -> 9433.9623 | H10: =IF($A10="", "", _xlfn.XLOOKUP($B10, YearlyParamsB!$A:$A, YearlyParamsB!$E:$E, 0)) -> 120000 | I10: =IF($A10="", "", E10*SGRate) -> 27600 | J10: =IFERROR(IF($A10="", "", _xlfn.XLOOKUP($B10, YearlyParamsB!$A:$A, YearlyParamsB!$I:$I, 0)), 0) -> 124900 | K10: =IFERROR(IF($A9="", "", IF(B10<>B9,0,Q9)), 0) -> 86668.985 | L10: =IFERROR(IF($A9="","",IF(B10<>B9, 0, L9 + MIN(G9+L9/PPYB, J9-K9)*F9)), 0) -> 40734.423 | M10: =IF($A10="", "", G10) -> 9433.9623 | N10: =IFERROR(IF($A10="", "", J10-K10), 0) -> 38231.015 | O10: =IFERROR(IF($A10="", "", MIN(G10,N10)), 0) -> 9433.9623 | P10: =IFERROR(IF($A10="", "", MIN(G10+L10/PPYB,N10)*F10 + MAX(0, MIN(G10+L10/PPYB,N10) - MIN(G10,N10))), 0) -> 9423.9291 | Q10: =IFERROR(IF($A10="", "", K10+MIN(G10+L10/PPYB,N10)), 0) -> 99497.482 | R10: =IFERROR(IF($A9="", "", IF(B10<>B9,P10,R9+P10)), 0) -> 61355.639 | S10: =IFERROR(IF($A10="", "", S9+P10), 0) -> 61355.639
A11: =IF(ROW()-1 <= TotalPeriodsB, ROW()-1, "") -> 10 | B11: =IF(ROW()-1 <= TotalPeriodsB, YEAR(StartYear) + INT((ROW()-2)/PPYB), "") -> 2027 | C11: =IF($A11="", "", MOD($A11-1, PPYB)+1) -> 10 | D11: =IF($A11="", "", C11=PPYB) -> FALSE | E11: =IF($A11="","",IncB*(1+Inflation)^((B11 - YEAR(StartYear)))) -> 230000 | F11: {=IF($A11="", "", MRate(E11))} -> 0.47 | G11: =IF($A11="", "", AfterTaxB/(1-F11)) -> 9433.9623 | H11: =IF($A11="", "", _xlfn.XLOOKUP($B11, YearlyParamsB!$A:$A, YearlyParamsB!$E:$E, 0)) -> 120000 | I11: =IF($A11="", "", E11*SGRate) -> 27600 | J11: =IFERROR(IF($A11="", "", _xlfn.XLOOKUP($B11, YearlyParamsB!$A:$A, YearlyParamsB!$I:$I, 0)), 0) -> 124900 | K11: =IFERROR(IF($A10="", "", IF(B11<>B10,0,Q10)), 0) -> 99497.482 | L11: =IFERROR(IF($A10="","",IF(B11<>B10, 0, L10 + MIN(G10+L10/PPYB, J10-K10)*F10)), 0) -> 46763.817 | M11: =IF($A11="", "", G11) -> 9433.9623 | N11: =IFERROR(IF($A11="", "", J11-K11), 0) -> 25402.518 | O11: =IFERROR(IF($A11="", "", MIN(G11,N11)), 0) -> 9433.9623 | P11: =IFERROR(IF($A11="", "", MIN(G11+L11/PPYB,N11)*F11 + MAX(0, MIN(G11+L11/PPYB,N11) - MIN(G11,N11))), 0) -> 10162.53 | Q11: =IFERROR(IF($A11="", "", K11+MIN(G11+L11/PPYB,N11)), 0) -> 112828.43 | R11: =IFERROR(IF($A10="", "", IF(B11<>B10,P11,R10+P11)), 0) -> 71518.169 | S11: =IFERROR(IF($A11="", "", S10+P11), 0) -> 71518.169
A12: =IF(ROW()-1 <= TotalPeriodsB, ROW()-1, "") -> 11 | B12: =IF(ROW()-1 <= TotalPeriodsB, YEAR(StartYear) + INT((ROW()-2)/PPYB), "") -> 2027 | C12: =IF($A12="", "", MOD($A12-1, PPYB)+1) -> 11 | D12: =IF($A12="", "", C12=PPYB) -> FALSE | E12: =IF($A12="","",IncB*(1+Inflation)^((B12 - YEAR(StartYear)))) -> 230000 | F12: {=IF($A12="", "", MRate(E12))} -> 0.47 | G12: =IF($A12="", "", AfterTaxB/(1-F12)) -> 9433.9623 | H12: =IF($A12="", "", _xlfn.XLOOKUP($B12, YearlyParamsB!$A:$A, YearlyParamsB!$E:$E, 0)) -> 120000 | I12: =IF($A12="", "", E12*SGRate) -> 27600 | J12: =IFERROR(IF($A12="", "", _xlfn.XLOOKUP($B12, YearlyParamsB!$A:$A, YearlyParamsB!$I:$I, 0)), 0) -> 124900 | K12: =IFERROR(IF($A11="", "", IF(B12<>B11,0,Q11)), 0) -> 112828.43 | L12: =IFERROR(IF($A11="","",IF(B12<>B11, 0, L11 + MIN(G11+L11/PPYB, J11-K11)*F11)), 0) -> 53029.362 | M12: =IF($A12="", "", G12) -> 9433.9623 | N12: =IFERROR(IF($A12="", "", J12-K12), 0) -> 12071.571 | O12: =IFERROR(IF($A12="", "", MIN(G12,N12)), 0) -> 9433.9623 | P12: =IFERROR(IF($A12="", "", MIN(G12+L12/PPYB,N12)*F12 + MAX(0, MIN(G12+L12/PPYB,N12) - MIN(G12,N12))), 0) -> 8311.2464 | Q12: =IFERROR(IF($A12="", "", K12+MIN(G12+L12/PPYB,N12)), 0) -> 124900 | R12: =IFERROR(IF($A11="", "", IF(B12<>B11,P12,R11+P12)), 0) -> 79829.415 | S12: =IFERROR(IF($A12="", "", S11+P12), 0) -> 79829.415
A13: =IF(ROW()-1 <= TotalPeriodsB, ROW()-1, "") -> 12 | B13: =IF(ROW()-1 <= TotalPeriodsB, YEAR(StartYear) + INT((ROW()-2)/PPYB), "") -> 2027 | C13: =IF($A13="", "", MOD($A13-1, PPYB)+1) -> 12 | D13: =IF($A13="", "", C13=PPYB) -> TRUE | E13: =IF($A13="","",IncB*(1+Inflation)^((B13 - YEAR(StartYear)))) -> 230000 | F13: {=IF($A13="", "", MRate(E13))} -> 0.47 | G13: =IF($A13="", "", AfterTaxB/(1-F13)) -> 9433.9623 | H13: =IF($A13="", "", _xlfn.XLOOKUP($B13, YearlyParamsB!$A:$A, YearlyParamsB!$E:$E, 0)) -> 120000 | I13: =IF($A13="", "", E13*SGRate) -> 27600 | J13: =IFERROR(IF($A13="", "", _xlfn.XLOOKUP($B13, YearlyParamsB!$A:$A, YearlyParamsB!$I:$I, 0)), 0) -> 124900 | K13: =IFERROR(IF($A12="", "", IF(B13<>B12,0,Q12)), 0) -> 124900 | L13: =IFERROR(IF($A12="","",IF(B13<>B12, 0, L12 + MIN(G12+L12/PPYB, J12-K12)*F12)), 0) -> 58703 | M13: =IF($A13="", "", G13) -> 9433.9623 | N13: =IFERROR(IF($A13="", "", J13-K13), 0) -> 0 | O13: =IFERROR(IF($A13="", "", MIN(G13,N13)), 0) -> 0 | P13: =IFERROR(IF($A13="", "", MIN(G13+L13/PPYB,N13)*F13 + MAX(0, MIN(G13+L13/PPYB,N13) - MIN(G13,N13))), 0) -> 0 | Q13: =IFERROR(IF($A13="", "", K13+MIN(G13+L13/PPYB,N13)), 0) -> 124900 | R13: =IFERROR(IF($A12="", "", IF(B13<>B12,P13,R12+P13)), 0) -> 79829.415 | S13: =IFERROR(IF($A13="", "", S12+P13), 0) -> 79829.415
A14: =IF(ROW()-1 <= TotalPeriodsB, ROW()-1, "") -> 13 | B14: =IF(ROW()-1 <= TotalPeriodsB, YEAR(StartYear) + INT((ROW()-2)/PPYB), "") -> 2028 | C14: =IF($A14="", "", MOD($A14-1, PPYB)+1) -> 1 | D14: =IF($A14="", "", C14=PPYB) -> FALSE | E14: =IF($A14="","",IncB*(1+Inflation)^((B14 - YEAR(StartYear)))) -> 235750 | F14: {=IF($A14="", "", MRate(E14))} -> 0.47 | G14: =IF($A14="", "", AfterTaxB/(1-F14)) -> 9433.9623 | H14: =IF($A14="", "", _xlfn.XLOOKUP($B14, YearlyParamsB!$A:$A, YearlyParamsB!$E:$E, 0)) -> 0 | I14: =IF($A14="", "", E14*SGRate) -> 28290 | J14: =IFERROR(IF($A14="", "", _xlfn.XLOOKUP($B14, YearlyParamsB!$A:$A, YearlyParamsB!$I:$I, 0)), 0) -> 4210 | K14: =IFERROR(IF($A13="", "", IF(B14<>B13,0,Q13)), 0) -> 0 | L14: =IFERROR(IF($A13="","",IF(B14<>B13, 0, L13 + MIN(G13+L13/PPYB, J13-K13)*F13)), 0) -> 0 | M14: =IF($A14="", "", G14) -> 9433.9623 | N14: =IFERROR(IF($A14="", "", J14-K14), 0) -> 4210 | O14: =IFERROR(IF($A14="", "", MIN(G14,N14)), 0) -> 4210 | P14: =IFERROR(IF($A14="", "", MIN(G14+L14/PPYB,N14)*F14 + MAX(0, MIN(G14+L14/PPYB,N14) - MIN(G14,N14))), 0) -> 1978.7 | Q14: =IFERROR(IF($A14="", "", K14+MIN(G14+L14/PPYB,N14)), 0) -> 4210 | R14: =IFERROR(IF($A13="", "", IF(B14<>B13,P14,R13+P14)), 0) -> 1978.7 | S14: =IFERROR(IF($A14="", "", S13+P14), 0) -> 81808.115
A15: =IF(ROW()-1 <= TotalPeriodsB, ROW()-1, "") -> 14 | B15: =IF(ROW()-1 <= TotalPeriodsB, YEAR(StartYear) + INT((ROW()-2)/PPYB), "") -> 2028 | C15: =IF($A15="", "", MOD($A15-1, PPYB)+1) -> 2 | D15: =IF($A15="", "", C15=PPYB) -> FALSE | E15: =IF($A15="","",IncB*(1+Inflation)^((B15 - YEAR(StartYear)))) -> 235750 | F15: {=IF($A15="", "", MRate(E15))} -> 0.47 | G15: =IF($A15="", "", AfterTaxB/(1-F15)) -> 9433.9623 | H15: =IF($A15="", "", _xlfn.XLOOKUP($B15, YearlyParamsB!$A:$A, YearlyParamsB!$E:$E, 0)) -> 0 | I15: =IF($A15="", "", E15*SGRate) -> 28290 | J15: =IFERROR(IF($A15="", "", _xlfn.XLOOKUP($B15, YearlyParamsB!$A:$A, YearlyParamsB!$I:$I, 0)), 0) -> 4210 | K15: =IFERROR(IF($A14="", "", IF(B15<>B14,0,Q14)), 0) -> 4210 | L15: =IFERROR(IF($A14="","",IF(B15<>B14, 0, L14 + MIN(G14+L14/PPYB, J14-K14)*F14)), 0) -> 1978.7 | M15: =IF($A15="", "", G15) -> 9433.9623 | N15: =IFERROR(IF($A15="", "", J15-K15), 0) -> 0 | O15: =IFERROR(IF($A15="", "", MIN(G15,N15)), 0) -> 0 | P15: =IFERROR(IF($A15="", "", MIN(G15+L15/PPYB,N15)*F15 + MAX(0, MIN(G15+L15/PPYB,N15) - MIN(G15,N15))), 0) -> 0 | Q15: =IFERROR(IF($A15="", "", K15+MIN(G15+L15/PPYB,N15)), 0) -> 4210 | R15: =IFERROR(IF($A14="", "", IF(B15<>B14,P15,R14+P15)), 0) -> 1978.7 | S15: =IFERROR(IF($A15="", "", S14+P15), 0) -> 81808.115
A16: =IF(ROW()-1 <= TotalPeriodsB, ROW()-1, "") -> 15 | B16: =IF(ROW()-1 <= TotalPeriodsB, YEAR(StartYear) + INT((ROW()-2)/PPYB), "") -> 2028 | C16: =IF($A16="", "", MOD($A16-1, PPYB)+1) -> 3 | D16: =IF($A16="", "", C16=PPYB) -> FALSE | E16: =IF($A16="","",IncB*(1+Inflation)^((B16 - YEAR(StartYear)))) -> 235750 | F16: {=IF($A16="", "", MRate(E16))} -> 0.47 | G16: =IF($A16="", "", AfterTaxB/(1-F16)) -> 9433.9623 | H16: =IF($A16="", "", _xlfn.XLOOKUP($B16, YearlyParamsB!$A:$A, YearlyParamsB!$E:$E, 0)) -> 0 | I16: =IF($A16="", "", E16*SGRate) -> 28290 | J16: =IFERROR(IF($A16="", "", _xlfn.XLOOKUP($B16, YearlyParamsB!$A:$A, YearlyParamsB!$I:$I, 0)), 0) -> 4210 | K16: =IFERROR(IF($A15="", "", IF(B16<>B15,0,Q15)), 0) -> 4210 | L16: =IFERROR(IF($A15="","",IF(B16<>B15, 0, L15 + MIN(G15+L15/PPYB, J15-K15)*F15)), 0) -> 1978.7 | M16: =IF($A16="", "", G16) -> 9433.9623 | N16: =IFERROR(IF($A16="", "", J16-K16), 0) -> 0 | O16: =IFERROR(IF($A16="", "", MIN(G16,N16)), 0) -> 0 | P16: =IFERROR(IF($A16="", "", MIN(G16+L16/PPYB,N16)*F16 + MAX(0, MIN(G16+L16/PPYB,N16) - MIN(G16,N16))), 0) -> 0 | Q16: =IFERROR(IF($A16="", "", K16+MIN(G16+L16/PPYB,N16)), 0) -> 4210 | R16: =IFERROR(IF($A15="", "", IF(B16<>B15,P16,R15+P16)), 0) -> 1978.7 | S16: =IFERROR(IF($A16="", "", S15+P16), 0) -> 81808.115
... A181: =IF(ROW()-1 <= TotalPeriodsB, ROW()-1, "") -> 180 | B181: =IF(ROW()-1 <= TotalPeriodsB, YEAR(StartYear) + INT((ROW()-2)/PPYB), "") -> 2041 | C181: =IF($A181="", "", MOD($A181-1, PPYB)+1) -> 12 | D181: =IF($A181="", "", C181=PPYB) -> TRUE | E181: =IF($A181="","",IncB*(1+Inflation)^((B181 - YEAR(StartYear)))) -> 324983.98 | F181: {=IF($A181="", "", MRate(E181))} -> 0.47 | G181: =IF($A181="", "", AfterTaxB/(1-F181)) -> 9433.9623 | H181: =IF($A181="", "", _xlfn.XLOOKUP($B181, YearlyParamsB!$A:$A, YearlyParamsB!$E:$E, 0)) -> 0 | I181: =IF($A181="", "", E181*SGRate) -> 38998.077 | J181: =IFERROR(IF($A181="", "", _xlfn.XLOOKUP($B181, YearlyParamsB!$A:$A, YearlyParamsB!$I:$I, 0)), 0) -> 11001.923 | K181: =IFERROR(IF($A180="", "", IF(B181<>B180,0,Q180)), 0) -> 11001.923 | L181: =IFERROR(IF($A180="","",IF(B181<>B180, 0, L180 + MIN(G180+L180/PPYB, J180-K180)*F180)), 0) -> 5170.9036 | M181: =IF($A181="", "", G181) -> 9433.9623 | N181: =IFERROR(IF($A181="", "", J181-K181), 0) -> 0 | O181: =IFERROR(IF($A181="", "", MIN(G181,N181)), 0) -> 0 | P181: =IFERROR(IF($A181="", "", MIN(G181+L181/PPYB,N181)*F181 + MAX(0, MIN(G181+L181/PPYB,N181) - MIN(G181,N181))), 0) -> 0 | Q181: =IFERROR(IF($A181="", "", K181+MIN(G181+L181/PPYB,N181)), 0) -> 11001.923 | R181: =IFERROR(IF($A180="", "", IF(B181<>B180,P181,R180+P181)), 0) -> 5170.9036 | S181: =IFERROR(IF($A181="", "", S180+P181), 0) -> 131613.46

Sheet Loan
A1: Scenario C: SuperSmart Strategy(Ofset & Annual Sweep) | AP1: LOAN COMPARISON SUMMARY
Q2: Scenario A: Current Trajectory (No offset or extra payment) | AC2: Scenario B: Extra after-tax payment to mortgage( no offset) | AX2: PeriodsPerYear | AY2: =_xlfn.XLOOKUP(FreqA,FreqLookup[Frequency],FreqLookup[PeriodsPerYear]) -> 12
A3: Period | B3: Year | C3: PeriodInYear | D3: OpeningBalance | E3: OffsetBeforeSweep | F3: EffectiveBalance | G3: Interest | H3: TotalPayment | I3: Principal | J3: ClosingBalance | K3: InterestSaved | L3: CumulativeInterestSaved | M3: CumulativeInterest | N3: CumulativePayments | O3: LoanYear | Q3: Period | R3: Year | S3: PeriodInYear | T3: OpeningBalance | U3: Interest | V3: TotalPayment | W3: Principal | X3: ClosingBalance | Y3: CumulativeInterest | Z3: CumulativePayments | AA3: LoanYear | AC3: Period | AD3: Year | AE3: PeriodInYear | AF3: OpeningBalance | AG3: Interest | AH3: TotalPayment | AI3: Principal | AJ3: ClosingBalance | AK3: CumulativeInterest | AL3: CumulativePayments | AM3: LoanYear | AP3: Metric | AR3: Scenario A: Current | AT3: Scenario B: Extra Payments | AV3: Scenario C: SuperSmart | AX3: TotalPeriods | AY3: =MAX(ProjYearsA,ProjYearsB)*PPY_Loan -> 180
